Workbook

Sheet Sheet1
A1: Pressure Transducer Calibration
A2: P (in. H20) | B2: V (Volts) | C2: Standard Deviation of V | D2: Uncertainty in V (95%) | E2: Uncertainty in P
A3: -3.3 | B3: -1.622 | C3: 0.029 | D3: =2*Table2[[#This Row],[Standard Deviation of V]] -> 0.058 | E3: 0.05
A4: 3.05 | B4: 1.316 | C4: 0.029 | D4: =2*Table2[[#This Row],[Standard Deviation of V]] -> 0.058 | E4: 0.05
A5: -0.7 | B5: -0.327 | C5: 0.026 | D5: =2*Table2[[#This Row],[Standard Deviation of V]] -> 0.052 | E5: 0.05
A9: Pressure transducer Calibration | D9: Atmospheric Conditions
A10: Slope (Calibration Constant) | B10: Uncertainty | D10: Temperature | E10: Pressure (hPa)
A11: ='Three Points'!K2 -> 2.166656 | B11: ='Three Points'!K6 -> 0.058121561 | D11: 23.9 | E11: 1015
A12: Intercept | B12: Uncertainty | D12: Humidity
A13: ='Three Points'!L2 -> 0.14049775 | B13: ='Three Points'!L6 -> 0.071521979
D15: Temp K | E15: Pressure (Pa)
A16: Wind Tunnel Calibration | D16: =CONVERT(D11,"C", "K") -> 297.05 | E16: =E11*100 -> 101500
A17: Slope (Calibration Constant) | B17: Uncertainty | E17: Density (kg/m^3)
A18: 0.5713 | B18: 0.025106 | E18: =E16/(287*D16) -> 1.1905691
A19: Intercept | B19: Uncertainty
A20: -0.296 | B20: 0.121
A23: Sutherlands Law | B23: Temperature | C23: Unit | D23: Viscosity | E23: Unit | F23: Sutherlands Constant | G23: Unit
A24: Reference | B24: 273.15 | C24: K | D24: 1.716e-05 | E24: Pa-s | F24: 111 | G24: K
A25: Actual (in lab units) | C25: F
A26: Actual (in SI unit) | B26: =CONVERT(B25,"F","K") -> 255.37222 | C26: K | D26: =D24*(B26/B24)^(2/3)*(B24+F24)/(B24-F24) -> 3.8870143e-05 | E26: Pa-s
A28: dynamic pressure | B28: velocity | C28: reynolds number | G28: 4 inch
A29: 2.445 | B29: =SQRT(2*A30/E18) -> 31.985015 | C29: =E18*B29*G29/D26 -> 99535.666 | F29: Lengthscale of airfoil: | G29: =CONVERT(4, "in", "m") -> 0.1016
A30: =A29*249.08 -> 609.0006
C31: 49.3
A34: Large Orifice diameter (in) | B34: 0.125
A35: Large Orifice diameter (mm) | B35: =CONVERT(B34,"in","mm") -> 3.175
A36: Large Orifice diameter (m) | B36: =CONVERT(B35, "mm", "m") -> 0.003175
A37: Large Orifice Area (m^2) | B37: =1/4 * B36^2 * PI() -> 7.9173044e-06
A38: Medium Orifice Diameter (in) | B38: 0.094
A39: Medium Orifice diameter (mm) | B39: =CONVERT(B38,"in","mm") -> 2.3876
A40: Medium Orifice diameter (m) | B40: =CONVERT(B39,"mm","m") -> 0.0023876
A41: Medium Orifice Area (m^2) | B41: =1/4 * B40^2 * PI() -> 4.4772673e-06
A42: Small Orufice diameter (in) | B42: 0.067
A43: Small Orifice diameter (mm) | B43: =CONVERT(B42,"in","mm") -> 1.7018
A44: Small Orifice diameter (m) | B44: =CONVERT(B43,"mm","m") -> 0.0017018
A45: Small Orifice area (m^2) | B45: =1/4 * B44^2 * PI() -> 2.2746099e-06
A46: Tank Volume (m^3) | B46: 0.125
A47: Room Pressure (kPa) | B47: 101
A48: gamma | B48: 1.4
A49: R | B49: 287
...

Sheet Three Points
B1: x1 | C1: x2 | D1: x3 | F1: y1 | G1: y2 | H1: y3 | K1: slope | L1: Intercept
A2: x,y values | B2: =Sheet1!B3 -> -1.622 | C2: =Sheet1!B4 -> 1.316 | D2: =Sheet1!B5 -> -0.327 | F2: =Sheet1!A3 -> -3.3 | G2: =Sheet1!A4 -> 3.05 | H2: =Sheet1!A5 -> -0.7 | K2: =SLOPE(F2:I2,B2:E2) -> 2.166656 | L2: =INTERCEPT(F2:H2,B2:D2) -> 0.14049775
B3: ux1 | C3: ux2 | D3: ux3 | F3: uy1 | G3: uy2 | H3: uy3 | N3: 95% CI | O3: =K5*2 -> 0.058121561
A4: --> 95% CI | B4: =Sheet1!E3 -> 0.05 | C4: =Table2[[#This Row],[Uncertainty in P ]] -> 0.05 | D4: =Sheet1!E5 -> 0.05 | F4: =Sheet1!D3 -> 0.058 | G4: =Table2[[#This Row],[Uncertainty in V (95%)]] -> 0.058 | H4: =Sheet1!D5 -> 0.052 | J4: average slope ---> | K4: =AVERAGE(K7:K10000) -> 2.1667828 | L4: =AVERAGE(L7:L10000) -> 0.14092828 | M4: <--- average intercept
J5: standard deviation of slope --> | K5: =STDEV(K7:K10000) -> 0.029060781 | L5: =STDEV(L7:L10000) -> 0.035760989
B6: x1' | C6: x2' | D6: x3' | F6: y1' | G6: y2' | H6: y3' | J6: Uncetainty in slope ---> | K6: =2*K5 -> 0.058121561 | L6: =2*L5 -> 0.071521979
B7: =_xlfn.NORM.INV(RAND(),B$2,B$4/2) -> -1.626457 | C7: =_xlfn.NORM.INV(RAND(),C$2,C$4/2) -> 1.3178896 | D7: =_xlfn.NORM.INV(RAND(),D$2,D$4/2) -> -0.3605263 | F7: =_xlfn.NORM.INV(RAND(),F$2,F$4/2) -> -3.2902976 | G7: =_xlfn.NORM.INV(RAND(),G$2,G$4/2) -> 3.0824561 | H7: =_xlfn.NORM.INV(RAND(),H$2,H$4/2) -> -0.6854908 | K7: =SLOPE(F7:H7,B7:D7) -> 2.1686634 | L7: =INTERCEPT(F7:H7,B7:D7) -> 0.18590227
B8: =_xlfn.NORM.INV(RAND(),B$2,B$4/2) -> -1.6000428 | C8: =_xlfn.NORM.INV(RAND(),C$2,C$4/2) -> 1.2892782 | D8: =_xlfn.NORM.INV(RAND(),D$2,D$4/2) -> -0.33772999 | F8: =_xlfn.NORM.INV(RAND(),F$2,F$4/2) -> -3.3271542 | G8: =_xlfn.NORM.INV(RAND(),G$2,G$4/2) -> 3.0748374 | H8: =_xlfn.NORM.INV(RAND(),H$2,H$4/2) -> -0.7471817 | K8: =SLOPE(F8:H8,B8:D8) -> 2.2220287 | L8: =INTERCEPT(F8:H8,B8:D8) -> 0.14715835
B9: =_xlfn.NORM.INV(RAND(),B$2,B$4/2) -> -1.6216937 | C9: =_xlfn.NORM.INV(RAND(),C$2,C$4/2) -> 1.2932242 | D9: =_xlfn.NORM.INV(RAND(),D$2,D$4/2) -> -0.30901216 | F9: =_xlfn.NORM.INV(RAND(),F$2,F$4/2) -> -3.2950063 | G9: =_xlfn.NORM.INV(RAND(),G$2,G$4/2) -> 3.0603604 | H9: =_xlfn.NORM.INV(RAND(),H$2,H$4/2) -> -0.65946401 | K9: =SLOPE(F9:H9,B9:D9) -> 2.1854188 | L9: =INTERCEPT(F9:H9,B9:D9) -> 0.16635152 | M9: 1
B10: =_xlfn.NORM.INV(RAND(),B$2,B$4/2) -> -1.6377732 | C10: =_xlfn.NORM.INV(RAND(),C$2,C$4/2) -> 1.3297355 | D10: =_xlfn.NORM.INV(RAND(),D$2,D$4/2) -> -0.35754292 | F10: =_xlfn.NORM.INV(RAND(),F$2,F$4/2) -> -3.2594667 | G10: =_xlfn.NORM.INV(RAND(),G$2,G$4/2) -> 3.0114163 | H10: =_xlfn.NORM.INV(RAND(),H$2,H$4/2) -> -0.72351773 | K10: =SLOPE(F10:H10,B10:D10) -> 2.1183689 | L10: =INTERCEPT(F10:H10,B10:D10) -> 0.14612571
B11: =_xlfn.NORM.INV(RAND(),B$2,B$4/2) -> -1.6367947 | C11: =_xlfn.NORM.INV(RAND(),C$2,C$4/2) -> 1.3456196 | D11: =_xlfn.NORM.INV(RAND(),D$2,D$4/2) -> -0.29764616 | F11: =_xlfn.NORM.INV(RAND(),F$2,F$4/2) -> -3.2965321 | G11: =_xlfn.NORM.INV(RAND(),G$2,G$4/2) -> 3.0412417 | H11: =_xlfn.NORM.INV(RAND(),H$2,H$4/2) -> -0.70184347 | K11: =SLOPE(F11:H11,B11:D11) -> 2.130751 | L11: =INTERCEPT(F11:H11,B11:D11) -> 0.099165932
B12: =_xlfn.NORM.INV(RAND(),B$2,B$4/2) -> -1.5962087 | C12: =_xlfn.NORM.INV(RAND(),C$2,C$4/2) -> 1.3338846 | D12: =_xlfn.NORM.INV(RAND(),D$2,D$4/2) -> -0.29036012 | F12: =_xlfn.NORM.INV(RAND(),F$2,F$4/2) -> -3.2782487 | G12: =_xlfn.NORM.INV(RAND(),G$2,G$4/2) -> 3.0365806 | H12: =_xlfn.NORM.INV(RAND(),H$2,H$4/2) -> -0.71658182 | K12: =SLOPE(F12:H12,B12:D12) -> 2.1613852 | L12: =INTERCEPT(F12:H12,B12:D12) -> 0.078771149
B13: =_xlfn.NORM.INV(RAND(),B$2,B$4/2) -> -1.6068839 | C13: =_xlfn.NORM.INV(RAND(),C$2,C$4/2) -> 1.325008 | D13: =_xlfn.NORM.INV(RAND(),D$2,D$4/2) -> -0.27879703 | F13: =_xlfn.NORM.INV(RAND(),F$2,F$4/2) -> -3.2651289 | G13: =_xlfn.NORM.INV(RAND(),G$2,G$4/2) -> 3.0337741 | H13: =_xlfn.NORM.INV(RAND(),H$2,H$4/2) -> -0.69667046 | K13: =SLOPE(F13:H13,B13:D13) -> 2.1544815 | L13: =INTERCEPT(F13:H13,B13:D13) -> 0.093311371
B14: =_xlfn.NORM.INV(RAND(),B$2,B$4/2) -> -1.6422565 | C14: =_xlfn.NORM.INV(RAND(),C$2,C$4/2) -> 1.3406766 | D14: =_xlfn.NORM.INV(RAND(),D$2,D$4/2) -> -0.33621065 | F14: =_xlfn.NORM.INV(RAND(),F$2,F$4/2) -> -3.2834849 | G14: =_xlfn.NORM.INV(RAND(),G$2,G$4/2) -> 3.0943622 | H14: =_xlfn.NORM.INV(RAND(),H$2,H$4/2) -> -0.72979964 | K14: =SLOPE(F14:H14,B14:D14) -> 2.1447134 | L14: =INTERCEPT(F14:H14,B14:D14) -> 0.1496518
B15: =_xlfn.NORM.INV(RAND(),B$2,B$4/2) -> -1.6537889 | C15: =_xlfn.NORM.INV(RAND(),C$2,C$4/2) -> 1.3299277 | D15: =_xlfn.NORM.INV(RAND(),D$2,D$4/2) -> -0.31597839 | F15: =_xlfn.NORM.INV(RAND(),F$2,F$4/2) -> -3.2838129 | G15: =_xlfn.NORM.INV(RAND(),G$2,G$4/2) -> 3.0881342 | H15: =_xlfn.NORM.INV(RAND(),H$2,H$4/2) -> -0.73183749 | K15: =SLOPE(F15:H15,B15:D15) -> 2.1425862 | L15: =INTERCEPT(F15:H15,B15:D15) -> 0.14779841
B16: =_xlfn.NORM.INV(RAND(),B$2,B$4/2) -> -1.6414728 | C16: =_xlfn.NORM.INV(RAND(),C$2,C$4/2) -> 1.3103801 | D16: =_xlfn.NORM.INV(RAND(),D$2,D$4/2) -> -0.32124171 | F16: =_xlfn.NORM.INV(RAND(),F$2,F$4/2) -> -3.2472629 | G16: =_xlfn.NORM.INV(RAND(),G$2,G$4/2) -> 3.0348649 | H16: =_xlfn.NORM.INV(RAND(),H$2,H$4/2) -> -0.65179233 | K16: =SLOPE(F16:H16,B16:D16) -> 2.1332835 | L16: =INTERCEPT(F16:H16,B16:D16) -> 0.17580797
B17: =_xlfn.NORM.INV(RAND(),B$2,B$4/2) -> -1.5980486 | C17: =_xlfn.NORM.INV(RAND(),C$2,C$4/2) -> 1.3309744 | D17: =_xlfn.NORM.INV(RAND(),D$2,D$4/2) -> -0.32715002 | F17: =_xlfn.NORM.INV(RAND(),F$2,F$4/2) -> -3.3822358 | G17: =_xlfn.NORM.INV(RAND(),G$2,G$4/2) -> 3.0984691 | H17: =_xlfn.NORM.INV(RAND(),H$2,H$4/2) -> -0.67169644 | K17: =SLOPE(F17:H17,B17:D17) -> 2.2156168 | L17: =INTERCEPT(F17:H17,B17:D17) -> 0.12036998
B18: =_xlfn.NORM.INV(RAND(),B$2,B$4/2) -> -1.6135665 | C18: =_xlfn.NORM.INV(RAND(),C$2,C$4/2) -> 1.304866 | D18: =_xlfn.NORM.INV(RAND(),D$2,D$4/2) -> -0.26334226 | F18: =_xlfn.NORM.INV(RAND(),F$2,F$4/2) -> -3.2915564 | G18: =_xlfn.NORM.INV(RAND(),G$2,G$4/2) -> 3.0667879 | H18: =_xlfn.NORM.INV(RAND(),H$2,H$4/2) -> -0.70578146 | K18: =SLOPE(F18:H18,B18:D18) -> 2.1847465 | L18: =INTERCEPT(F18:H18,B18:D18) -> 0.10640619
B19: =_xlfn.NORM.INV(RAND(),B$2,B$4/2) -> -1.5972331 | C19: =_xlfn.NORM.INV(RAND(),C$2,C$4/2) -> 1.320942 | D19: =_xlfn.NORM.INV(RAND(),D$2,D$4/2) -> -0.32298641 | F19: =_xlfn.NORM.INV(RAND(),F$2,F$4/2) -> -3.2878463 | G19: =_xlfn.NORM.INV(RAND(),G$2,G$4/2) -> 3.0733972 | H19: =_xlfn.NORM.INV(RAND(),H$2,H$4/2) -> -0.72870763 | K19: =SLOPE(F19:H19,B19:D19) -> 2.1861619 | L19: =INTERCEPT(F19:H19,B19:D19) -> 0.12232029
B20: =_xlfn.NORM.INV(RAND(),B$2,B$4/2) -> -1.5917199 | C20: =_xlfn.NORM.INV(RAND(),C$2,C$4/2) -> 1.3203592 | D20: =_xlfn.NORM.INV(RAND(),D$2,D$4/2) -> -0.29149116 | F20: =_xlfn.NORM.INV(RAND(),F$2,F$4/2) -> -3.3441858 | G20: =_xlfn.NORM.INV(RAND(),G$2,G$4/2) -> 3.0148536 | H20: =_xlfn.NORM.INV(RAND(),H$2,H$4/2) -> -0.70999211 | K20: =SLOPE(F20:H20,B20:D20) -> 2.1886818 | L20: =INTERCEPT(F20:H20,B20:D20) -> 0.064193051
B21: =_xlfn.NORM.INV(RAND(),B$2,B$4/2) -> -1.600293 | C21: =_xlfn.NORM.INV(RAND(),C$2,C$4/2) -> 1.3196513 | D21: =_xlfn.NORM.INV(RAND(),D$2,D$4/2) -> -0.35697258 | F21: =_xlfn.NORM.INV(RAND(),F$2,F$4/2) -> -3.3206402 | G21: =_xlfn.NORM.INV(RAND(),G$2,G$4/2) -> 3.0586322 | H21: =_xlfn.NORM.INV(RAND(),H$2,H$4/2) -> -0.697014 | K21: =SLOPE(F21:H21,B21:D21) -> 2.1878414 | L21: =INTERCEPT(F21:H21,B21:D21) -> 0.14532561
... B10806: =_xlfn.NORM.INV(RAND(),B$2,B$4/2) -> -1.6270076 | C10806: =_xlfn.NORM.INV(RAND(),C$2,C$4/2) -> 1.3279825 | D10806: =_xlfn.NORM.INV(RAND(),D$2,D$4/2) -> -0.31405273 | F10806: =_xlfn.NORM.INV(RAND(),F$2,F$4/2) -> -3.282937 | G10806: =_xlfn.NORM.INV(RAND(),G$2,G$4/2) -> 3.0486476 | H10806: =_xlfn.NORM.INV(RAND(),H$2,H$4/2) -> -0.71208504 | K10806: =SLOPE(F10806:H10806,B10806:D10806) -> 2.1487401 | L10806: =INTERCEPT(F10806:H10806,B10806:D10806) -> 0.12365679
